Workbook
Name SegmentaciónDeDatos_Organización_compras: #N/A
Name SegmentaciónDeDatos_Tipo: #N/A

Sheet BB_DD
A1: Centro | B1: País | C1: Organización compras | D1: Grupo de compras | E1: G.compras | F1: Solicitante | G1: Tipo | H1: Solicitud de pedido | I1: Posición de pedido | J1: Pedido | K1: Texto breve | L1: Fecha de solicitud | M1: Creado por | N1: Clase documento | O1: Grupo de artículos | P1: Proveedor fijo | Q1: Nombre de proveedor | R1: Valor total | S1: Valor total USD | T1: Moneda | U1: Indicador de borrado
A2: BIN | B2: =LEFT(Tabla1[[#This Row],[Organización compras]],2) -> CL | C2: CL01 | D2: 634 | E2: =VLOOKUP(Tabla1[[#This Row],[Grupo de compras]],'Grupo compras'!$A$1:$B$115,2,FALSE) -> CL Proyectos 5 | F2: RSOUPER | G2: =LEFT(Tabla1[[#This Row],[Solicitud de pedido]],2) -> 13 | H2: 1300008890 | I2: 10 | J2: 5000008621 | K2: Construcción Outlet Buin | L2: 46056 | M2: EXT_AYEPEZ | N2: ZSPC | P2: 96869030 | Q2: CONSTRUCTORA CUEVAS Y PURCELL S.A. | R2: 325400 | S2: =Tabla1[[#This Row],[Valor total]]/'T.C.'!$B$4 -> 13558333 | T2: UF | U2: false
A3: AEB | B3: =LEFT(Tabla1[[#This Row],[Organización compras]],2) -> CL | C3: CL01 | D3: 634 | E3: =VLOOKUP(Tabla1[[#This Row],[Grupo de compras]],'Grupo compras'!$A$1:$B$115,2,FALSE) -> CL Proyectos 5 | F3: RSOUPER | G3: =LEFT(Tabla1[[#This Row],[Solicitud de pedido]],2) -> 13 | H3: 1300008897 | I3: 10 | J3: 5000008640 | K3: Reconversión Adidas | L3: 46065 | M3: EXT_AYEPEZ | N3: ZSPC | P3: 77058836 | Q3: LUNA NESVARA CONSTRUCTORA SPA | R3: 10231 | S3: =Tabla1[[#This Row],[Valor total]]/'T.C.'!$B$4 -> 426291.67 | T3: UF | U3: false
A4: 1100 | B4: =LEFT(Tabla1[[#This Row],[Organización compras]],2) -> CL | C4: CL01 | D4: 911 | E4: =VLOOKUP(Tabla1[[#This Row],[Grupo de compras]],'Grupo compras'!$A$1:$B$115,2,FALSE) -> Corp A. Finanzas | F4: atoloza | G4: =LEFT(Tabla1[[#This Row],[Solicitud de pedido]],2) -> 14 | H4: 1400009325 | I4: 10 | J4: 5400006839 | K4: Comisiones pendientes – Roles RTB y Banc | L4: 46084 | M4: PMUNOZ | N4: ZPMH | P4: 97036000 | Q4: BANCO SANTANDER CHILE | R4: 363745833 | S4: =Tabla1[[#This Row],[Valor total]]/'T.C.'!$B$3 -> 392843.77 | T4: CLP | U4: false
A5: MIN | B5: =LEFT(Tabla1[[#This Row],[Organización compras]],2) -> PE | C5: PE01 | D5: 802 | E5: =VLOOKUP(Tabla1[[#This Row],[Grupo de compras]],'Grupo compras'!$A$1:$B$115,2,FALSE) -> PE Ops Mall | F5: cpisfil | G5: =LEFT(Tabla1[[#This Row],[Solicitud de pedido]],2) -> 13 | H5: 1300008836 | I5: 10 | J5: 5000008576 | K5: SRV ADMINIST. DE ESTACI _2026 | L5: 46042 | M5: EXT_EDAVILA | N5: ZSPC | P5: P60338169 | Q5: INVERSIONES URBANISTICAS OPERADORA | R5: 1112964 | S5: =Tabla1[[#This Row],[Valor total]]/'T.C.'!$B$2 -> 322598.26 | T5: PEN | U5: false
A6: 1100 | B6: =LEFT(Tabla1[[#This Row],[Organización compras]],2) -> CL | C6: CL01 | D6: 635 | E6: =VLOOKUP(Tabla1[[#This Row],[Grupo de compras]],'Grupo compras'!$A$1:$B$115,2,FALSE) -> CL Proyectos 6 | F6: CGARCI | G6: =LEFT(Tabla1[[#This Row],[Solicitud de pedido]],2) -> 12 | H6: 1200144791 | I6: 10 | J6: 4900149406 | K6: HITO 3 etapa 2B | L6: 46051 | M6: EXT_AYEPEZ | N6: ZSRV | P6: 76451328 | Q6: MESA ARQUITECTURA LIMITADA | R6: 6513.2 | S6: =Tabla1[[#This Row],[Valor total]]/'T.C.'!$B$4 -> 271383.33 | T6: UF | U6: false
A7: 6000 | B7: =LEFT(Tabla1[[#This Row],[Organización compras]],2) -> PE | C7: PEMP | D7: 816 | E7: =VLOOKUP(Tabla1[[#This Row],[Grupo de compras]],'Grupo compras'!$A$1:$B$115,2,FALSE) -> PE Sgcia Infra | F7: MMURGUIA | G7: =LEFT(Tabla1[[#This Row],[Solicitud de pedido]],2) -> 13 | H7: 1300008879 | I7: 10 | J7: 5000008617 | K7: Mesas, sillas y tachos de basura - Distr | L7: 46055 | M7: EXT_ACHIHUAN | N7: ZSPC | P7: P51281489 | Q7: G. SEMPERTEGUI PROYECTOS GENERAL | R7: 556010.94 | S7: =Tabla1[[#This Row],[Valor total]]/'T.C.'!$B$2 -> 161162.59 | T7: PEN | U7: false
A8: 6000 | B8: =LEFT(Tabla1[[#This Row],[Organización compras]],2) -> PE | C8: PEMP | D8: 811 | E8: =VLOOKUP(Tabla1[[#This Row],[Grupo de compras]],'Grupo compras'!$A$1:$B$115,2,FALSE) -> PE Área Admin | F8: JRODRIGUEZS | G8: =LEFT(Tabla1[[#This Row],[Solicitud de pedido]],2) -> 12 | H8: 1200143922 | I8: 10 | J8: 4900148645 | K8: Lucro Cesante por perdida de venta gener | L8: 46034 | M8: GRAVINES | N8: ZSRV | O8: SER_GRAL | P8: P33756437 | Q8: TIENDAS POR DEPARTAMENTO RIPLEY S.A | R8: 531274 | S8: =Tabla1[[#This Row],[Valor total]]/'T.C.'!$B$2 -> 153992.46 | T8: PEN | U8: false
A9: 6000 | B9: =LEFT(Tabla1[[#This Row],[Organización compras]],2) -> PE | C9: PEMP | D9: 816 | E9: =VLOOKUP(Tabla1[[#This Row],[Grupo de compras]],'Grupo compras'!$A$1:$B$115,2,FALSE) -> PE Sgcia Infra | F9: MMURGUIA | G9: =LEFT(Tabla1[[#This Row],[Solicitud de pedido]],2) -> 13 | H9: 1300008891 | I9: 10 | J9: 5000008631 | K9: Supervisión MP Independencia Distrito Ga | L9: 46057 | M9: EXT_ACHIHUAN | N9: ZSPC | P9: P10228549 | Q9: SCHMIDT & CHAVEZ TAFUR INGENIEROS S | R9: 511117.48 | S9: =Tabla1[[#This Row],[Valor total]]/'T.C.'!$B$2 -> 148149.99 | T9: PEN | U9: false
A10: 1100 | B10: =LEFT(Tabla1[[#This Row],[Organización compras]],2) -> CL | C10: CL01 | D10: 914 | E10: =VLOOKUP(Tabla1[[#This Row],[Grupo de compras]],'Grupo compras'!$A$1:$B$115,2,FALSE) -> Corp Explo. TI | F10: CPAVEZ | G10: =LEFT(Tabla1[[#This Row],[Solicitud de pedido]],2) -> 12 | H10: 1200143992 | I10: 10 | J10: 4900148769 | K10: RENOVACION LICENCIAS ATLASSIAN | L10: 46036 | M10: CPAVEZ | N10: ZSRV | O10: SER_GRAL | P10: 76924900 | Q10: TSOFT CHILE SPA | R10: 142350 | S10: =Tabla1[[#This Row],[Valor total]] -> 142350 | T10: USD | U10: false
A11: MQU | B11: =LEFT(Tabla1[[#This Row],[Organización compras]],2) -> CL | C11: CL01 | D11: 602 | E11: =VLOOKUP(Tabla1[[#This Row],[Grupo de compras]],'Grupo compras'!$A$1:$B$115,2,FALSE) -> CL Ops Mall | F11: MBELLO | G11: =LEFT(Tabla1[[#This Row],[Solicitud de pedido]],2) -> 12 | H11: 1200144958 | I11: 10 | J11: 4900149553 | K11: Analiticas MAQ cctv etapa final | L11: 46056 | M11: EXT_MBELLO | N11: ZSRV | P11: 77350771 | Q11: 4EVER GROUP SPA | R11: 124249365 | S11: =Tabla1[[#This Row],[Valor total]]/'T.C.'!$B$3 -> 134188.72 | T11: CLP | U11: false
A12: 6740 | B12: =LEFT(Tabla1[[#This Row],[Organización compras]],2) -> PE | C12: PEMP | D12: 816 | E12: =VLOOKUP(Tabla1[[#This Row],[Grupo de compras]],'Grupo compras'!$A$1:$B$115,2,FALSE) -> PE Sgcia Infra | F12: MMURGUIA | H12: 1300008966 | I12: 10 | J12: 5000008689 | K12: Obra para Habilitación Urbana de Vía REA | L12: 46092 | M12: EXT_ACHIHUAN | N12: ZSPC | P12: P60285686 | Q12: GESVAL S.A.C | R12: 451000 | S12: =Tabla1[[#This Row],[Valor total]]/'T.C.'!$B$2 -> 130724.64 | T12: PEN | U12: false
A13: 6000 | B13: =LEFT(Tabla1[[#This Row],[Organización compras]],2) -> PE | C13: PEMP | D13: 811 | E13: =VLOOKUP(Tabla1[[#This Row],[Grupo de compras]],'Grupo compras'!$A$1:$B$115,2,FALSE) -> PE Área Admin | F13: JRODRIGUEZS | G13: =LEFT(Tabla1[[#This Row],[Solicitud de pedido]],2) -> 12 | H13: 1200146527 | I13: 10 | J13: 4900150865 | K13: Lucro Cesante por perdida de venta gener | L13: 46083 | M13: GRAVINES | N13: ZSRV | O13: SER_GRAL | P13: P33756437 | Q13: TIENDAS POR DEPARTAMENTO RIPLEY S.A | R13: 405165 | S13: =Tabla1[[#This Row],[Valor total]]/'T.C.'!$B$2 -> 117439.13 | T13: PEN | U13: false
A14: MIN | B14: =LEFT(Tabla1[[#This Row],[Organización compras]],2) -> PE | C14: PE01 | D14: 801 | E14: =VLOOKUP(Tabla1[[#This Row],[Grupo de compras]],'Grupo compras'!$A$1:$B$115,2,FALSE) -> PE Center Manager | F14: jbalcazar | G14: =LEFT(Tabla1[[#This Row],[Solicitud de pedido]],2) -> 13 | H14: 1300008843 | I14: 10 | J14: 5000008569 | K14: SRV PERSONAL SEG. ENE-DIC26 | L14: 46041 | M14: EXT_EDAVILA | N14: ZSPC | P14: P60307606 | Q14: SESEPOL PERU S.A.C. | R14: 398418 | S14: =Tabla1[[#This Row],[Valor total]]/'T.C.'!$B$2 -> 115483.48 | T14: PEN | U14: false
A15: 6000 | B15: =LEFT(Tabla1[[#This Row],[Organización compras]],2) -> PE | C15: PEMP | D15: 816 | E15: =VLOOKUP(Tabla1[[#This Row],[Grupo de compras]],'Grupo compras'!$A$1:$B$115,2,FALSE) -> PE Sgcia Infra | F15: AGALVAN | G15: =LEFT(Tabla1[[#This Row],[Solicitud de pedido]],2) -> 13 | H15: 1300008946 | I15: 10 | J15: 5000008670 | K15: PLAN DE MITIGACIÓN MPI | L15: 46085 | M15: EXT_ACHIHUAN | N15: ZSPC | O15: SER_GRAL | P15: P42465666 | Q15: EDIFICACIONES DEL SUR S.A.C. | R15: 393069.43 | S15: =Tabla1[[#This Row],[Valor total]]/'T.C.'!$B$2 -> 113933.17 | T15: PEN | U15: false
A16: 1100 | B16: =LEFT(Tabla1[[#This Row],[Organización compras]],2) -> CL | C16: CL01 | D16: 930 | E16: =VLOOKUP(Tabla1[[#This Row],[Grupo de compras]],'Grupo compras'!$A$1:$B$115,2,FALSE) -> Corp Desarro. TI | F16: CVERGARA | G16: =LEFT(Tabla1[[#This Row],[Solicitud de pedido]],2) -> 12 | H16: 1200146393 | I16: 10 | J16: 4900150608 | K16: HubSpot 2026 | L16: 46079 | M16: CVERGARA | N16: ZSRV | O16: SER_GRAL | P16: 20263279 | Q16: HUBSPOT, INC. | R16: 110996.82 | S16: =Tabla1[[#This Row],[Valor total]] -> 110996.82 | T16: USD | U16: false
A17: 2400 | B17: =LEFT(Tabla1[[#This Row],[Organización compras]],2) -> CL | C17: CL01 | D17: 602 | E17: =VLOOKUP(Tabla1[[#This Row],[Grupo de compras]],'Grupo compras'!$A$1:$B$115,2,FALSE) -> CL Ops Mall | F17: p.herrera | G17: =LEFT(Tabla1[[#This Row],[Solicitud de pedido]],2) -> 13 | H17: 1300008825 | I17: 10 | J17: 5000008556 | K17: Proyecto Paneles FV CAL | L17: 46029 | M17: EXT_PHERRERA | N17: ZSPC | P17: 76172285 | Q17: COPEC FLUX SPA | R17: 2557.5 | S17: =Tabla1[[#This Row],[Valor total]]/'T.C.'!$B$4 -> 106562.5 | T17: UF | U17: false
A18: 1100 | B18: =LEFT(Tabla1[[#This Row],[Organización compras]],2) -> CL | C18: CL01 | D18: 613 | E18: =VLOOKUP(Tabla1[[#This Row],[Grupo de compras]],'Grupo compras'!$A$1:$B$115,2,FALSE) -> CL Gcia Ops | F18: p.herrera | G18: =LEFT(Tabla1[[#This Row],[Solicitud de pedido]],2) -> 12 | H18: 1200144667 | I18: 10 | J18: 4900149369 | K18: ASESORIA MERCADO ELECTRICO 2026 | L18: 46049 | M18: EXT_PHERRERA | N18: ZSRV | O18: SER_GRAL | P18: 78585040 | Q18: ASESORIAS Y RENTAS ECLIPSE LTDA | R18: 2500 | S18: =Tabla1[[#This Row],[Valor total]]/'T.C.'!$B$4 -> 104166.67 | T18: UF | U18: false
A19: MIN | B19: =LEFT(Tabla1[[#This Row],[Organización compras]],2) -> PE | C19: PE01 | D19: 802 | E19: =VLOOKUP(Tabla1[[#This Row],[Grupo de compras]],'Grupo compras'!$A$1:$B$115,2,FALSE) -> PE Ops Mall | F19: CPISFIL | G19: =LEFT(Tabla1[[#This Row],[Solicitud de pedido]],2) -> 13 | H19: 1300008882 | I19: 10 | J19: 5000008624 | K19: LIMPIEZA DE TECHOS 2026 | L19: 46057 | M19: EXT_EDAVILA | N19: ZSPC | P19: P60170752 | Q19: GROUP ANMI BLASTER S.A.C. | R19: 333727.08 | S19: =Tabla1[[#This Row],[Valor total]]/'T.C.'!$B$2 -> 96732.487 | T19: PEN | U19: false
A20: MQU | B20: =LEFT(Tabla1[[#This Row],[Organización compras]],2) -> CL | C20: CL01 | D20: 634 | E20: =VLOOKUP(Tabla1[[#This Row],[Grupo de compras]],'Grupo compras'!$A$1:$B$115,2,FALSE) -> CL Proyectos 5 | F20: RMOYA | G20: =LEFT(Tabla1[[#This Row],[Solicitud de pedido]],2) -> 13 | H20: 1300008862 | I20: 10 | J20: 5000008593 | K20: Etapa 1 MasterMAQ | L20: 46048 | M20: EXT_AYEPEZ | N20: ZSPC | P20: 76054243 | Q20: G5 ARQUITECTOS S.A. | R20: 2293.58 | S20: =Tabla1[[#This Row],[Valor total]]/'T.C.'!$B$4 -> 95565.833 | T20: UF | U20: false
A21: 4300 | B21: =LEFT(Tabla1[[#This Row],[Organización compras]],2) -> CO | C21: CO01 | D21: 702 | E21: =VLOOKUP(Tabla1[[#This Row],[Grupo de compras]],'Grupo compras'!$A$1:$B$115,2,FALSE) -> CO Ops Mall | F21: ARICO | G21: =LEFT(Tabla1[[#This Row],[Solicitud de pedido]],2) -> 13 | H21: 1300008906 | I21: 10 | J21: 5000008650 | K21: CAPEX TTVV PAR F3 - 2026 | L21: 46072 | M21: EXT_JTRUJILL | N21: ZSPC | P21: C860005289 | Q21: ASCENSORES SCHINDLER DE COLOMBIA S. | R21: 341457665 | S21: =Tabla1[[#This Row],[Valor total]]/'T.C.'!$B$5 -> 92837.864 | T21: COP | U21: false
A22: 4300 | B22: =LEFT(Tabla1[[#This Row],[Organización compras]],2) -> CO | C22: CO01 | D22: 719 | E22: =VLOOKUP(Tabla1[[#This Row],[Grupo de compras]],'Grupo compras'!$A$1:$B$115,2,FALSE) -> CO Gcia Ing | F22: JVASQUEZ | G22: =LEFT(Tabla1[[#This Row],[Solicitud de pedido]],2) -> 13 | H22: 1300008961 | I22: 10 | J22: 5000008679 | K22: 4.2.1 Ventilacion mecanica pecera S1 Arb | L22: 46087 | M22: JVASQUEZ | N22: ZSPC | P22: C890402550 | Q22: AIRE CARIBE S.A | R22: 308097828 | S22: =Tabla1[[#This Row],[Valor total]]/'T.C.'!$B$5 -> 83767.762 | T22: COP | U22: false
A23: 1100 | B23: =LEFT(Tabla1[[#This Row],[Organización compras]],2) -> CL | C23: CL01 | D23: 930 | E23: =VLOOKUP(Tabla1[[#This Row],[Grupo de compras]],'Grupo compras'!$A$1:$B$115,2,FALSE) -> Corp Desarro. TI | F23: KBOYE | G23: =LEFT(Tabla1[[#This Row],[Solicitud de pedido]],2) -> 12 | H23: 1200144420 | I23: 10 | J23: 4900148958 | K23: SOM: SAP BTP y API AWS | L23: 46044 | M23: KBOYE | N23: ZSRV | P23: 77050473 | Q23: STL METACONSULTING SPA | R23: 1994 | S23: =Tabla1[[#This Row],[Valor total]]/'T.C.'!$B$4 -> 83083.333 | T23: UF | U23: false
A24: 1100 | B24: =LEFT(Tabla1[[#This Row],[Organización compras]],2) -> CL | C24: CL01 | D24: 604 | E24: =VLOOKUP(Tabla1[[#This Row],[Grupo de compras]],'Grupo compras'!$A$1:$B$115,2,FALSE) -> CL Marketing Mall | F24: IIBANEZ | G24: =LEFT(Tabla1[[#This Row],[Solicitud de pedido]],2) -> 13 | H24: 1300008826 | I24: 10 | J24: 5000008555 | K24: CONTRATO STITCH | L24: 46029 | M24: IIBANEZ | N24: ZSPC | P24: 99557160 | Q24: CINECOLOR FILMS CHILE SPA. | R24: 76035000 | S24: =Tabla1[[#This Row],[Valor total]]/'T.C.'!$B$3 -> 82117.439 | T24: CLP | U24: false
A25: MIN | B25: =LEFT(Tabla1[[#This Row],[Organización compras]],2) -> PE | C25: PE01 | D25: 802 | E25: =VLOOKUP(Tabla1[[#This Row],[Grupo de compras]],'Grupo compras'!$A$1:$B$115,2,FALSE) -> PE Ops Mall | F25: cpisfil | H25: 1300008965 | I25: 10 | J25: 5000008688 | K25: Filtros para agua de pozo Minka | L25: 46092 | M25: EXT_EDAVILA | N25: ZSPC | P25: P38820311 | Q25: NCH PERU S.A | R25: 80000 | S25: =Tabla1[[#This Row],[Valor total]] -> 80000 | T25: USD | U25: false
A26: 1100 | B26: =LEFT(Tabla1[[#This Row],[Organización compras]],2) -> CL | C26: CL01 | D26: 928 | E26: =VLOOKUP(Tabla1[[#This Row],[Grupo de compras]],'Grupo compras'!$A$1:$B$115,2,FALSE) -> Corp Gest Riesgo | F26: cfuentes | G26: =LEFT(Tabla1[[#This Row],[Solicitud de pedido]],2) -> 14 | H26: 1400009185 | I26: 20 | J26: 5400006752 | K26: Endoso inclusión Mall IV Subterráneos - | L26: 46044 | M26: PMUNOZ | N26: ZPMH | P26: 99288000 | Q26: SOUTHBRIDGE COMPANIA DE SEGUROS | R26: 1861.63 | S26: =Tabla1[[#This Row],[Valor total]]/'T.C.'!$B$4 -> 77567.917 | T26: UF | U26: false
A27: BOG | B27: =LEFT(Tabla1[[#This Row],[Organización compras]],2) -> CO | C27: CO01 | D27: 702 | E27: =VLOOKUP(Tabla1[[#This Row],[Grupo de compras]],'Grupo compras'!$A$1:$B$115,2,FALSE) -> CO Ops Mall | F27: CAROL CORTES | G27: =LEFT(Tabla1[[#This Row],[Solicitud de pedido]],2) -> 13 | H27: 1300008930 | I27: 10 | J27: 5000008651 | K27: PARKING GASTO ESTACIONA MARZO A DIC 2026 | L27: 46073 | M27: EXT_APAREDES | N27: ZSPC | P27: C900038616 | Q27: CBRE COLOMBIA SAS | R27: 258044630 | S27: =Tabla1[[#This Row],[Valor total]]/'T.C.'!$B$5 -> 70158.953 | T27: COP | U27: false
A28: 1100 | B28: =LEFT(Tabla1[[#This Row],[Organización compras]],2) -> CL | C28: CL01 | D28: 907 | E28: =VLOOKUP(Tabla1[[#This Row],[Grupo de compras]],'Grupo compras'!$A$1:$B$115,2,FALSE) -> Corp Desarrollo | F28: AHERRERA | H28: 1300008959 | I28: 10 | J28: 5000008687 | K28: Mall Paseo Quilín | L28: 46092 | M28: DQUINTANA | N28: ZSPC | P28: 82586835 | Q28: BROADWAY MALYAN ESPAÑA ARQUITECTOS | R28: 70000 | S28: =Tabla1[[#This Row],[Valor total]] -> 70000 | T28: USD | U28: false
A29: ACO | B29: =LEFT(Tabla1[[#This Row],[Organización compras]],2) -> CL | C29: CL01 | D29: 602 | E29: =VLOOKUP(Tabla1[[#This Row],[Grupo de compras]],'Grupo compras'!$A$1:$B$115,2,FALSE) -> CL Ops Mall | F29: FGONZALEZ | G29: =LEFT(Tabla1[[#This Row],[Solicitud de pedido]],2) -> 12 | H29: 1200145379 | I29: 10 | J29: 4900149938 | K29: Equipamiento Fortinet Backbone | L29: 46063 | M29: FGONZALEZG | N29: ZSRV | P29: 77884668 | Q29: IT MORE SPA | R29: 69264.64 | S29: =Tabla1[[#This Row],[Valor total]] -> 69264.64 | T29: USD | U29: false
A30: 1100 | B30: =LEFT(Tabla1[[#This Row],[Organización compras]],2) -> CL | C30: CL01 | D30: 622 | E30: =VLOOKUP(Tabla1[[#This Row],[Grupo de compras]],'Grupo compras'!$A$1:$B$115,2,FALSE) -> CL Arq Mall | F30: P RAMIREZ | G30: =LEFT(Tabla1[[#This Row],[Solicitud de pedido]],2) -> 13 | H30: 1300008885 | I30: 10 | J30: 5000008633 | K30: SERV INSP TECNICA LOCALES PAK 2026 | L30: 46059 | M30: BILLESCA | N30: ZSPC | P30: 76088833 | Q30: ASESORIAS E INVERSIONES FAUNDEZ LAT | R30: 1640 | S30: =Tabla1[[#This Row],[Valor total]]/'T.C.'!$B$4 -> 68333.333 | T30: UF | U30: false
A31: 1100 | B31: =LEFT(Tabla1[[#This Row],[Organización compras]],2) -> CL | C31: CL01 | D31: 914 | E31: =VLOOKUP(Tabla1[[#This Row],[Grupo de compras]],'Grupo compras'!$A$1:$B$115,2,FALSE) -> Corp Explo. TI | F31: ACARVAJAL | G31: =LEFT(Tabla1[[#This Row],[Solicitud de pedido]],2) -> 12 | H31: 1200144090 | I31: 10 | J31: 4900148892 | K31: Globant Salesforce Core 2026 | L31: 46037 | M31: ACARVAJAL | N31: ZSRV | O31: SER_GRAL | P31: 76411210 | Q31: SISTEMAS GLOBALES CHILE-ASESORIAS | R31: 1608 | S31: =Tabla1[[#This Row],[Valor total]]/'T.C.'!$B$4 -> 67000 | T31: UF | U31: false
A32: 3100 | B32: =LEFT(Tabla1[[#This Row],[Organización compras]],2) -> PE | C32: PE01 | D32: 808 | E32: =VLOOKUP(Tabla1[[#This Row],[Grupo de compras]],'Grupo compras'!$A$1:$B$115,2,FALSE) -> PE Área Legal | F32: GOLIVERI | G32: =LEFT(Tabla1[[#This Row],[Solicitud de pedido]],2) -> 12 | H32: 1200145069 | I32: 10 | J32: 4900149771 | K32: Dieta Director Periodo - Ene a Dic 2026 | L32: 46058 | M32: SGARIBAY | N32: ZSRV | P32: P07276734 | Q32: CESAR EMILIO RODRIGUEZ LARRAIN SALI | R32: 65217.39 | S32: =Tabla1[[#This Row],[Valor total]] -> 65217.39 | T32: USD | U32: false
A33: 1100 | B33: =LEFT(Tabla1[[#This Row],[Organización compras]],2) -> CL | C33: CL01 | D33: 928 | E33: =VLOOKUP(Tabla1[[#This Row],[Grupo de compras]],'Grupo compras'!$A$1:$B$115,2,FALSE) -> Corp Gest Riesgo | F33: cfuentes | H33: 1400009354 | I33: 10 | J33: 5400006845 | K33: Endoso prórroga Responsabilidad Civil Ma | L33: 46094 | M33: PMUNOZ | N33: ZPMH | P33: 99225000 | Q33: CHUBB SEGUROS CHILE S.A. | R33: 1478.08 | S33: =Tabla1[[#This Row],[Valor total]]/'T.C.'!$B$4 -> 61586.667 | T33: UF | U33: false
A34: 2400 | B34: =LEFT(Tabla1[[#This Row],[Organización compras]],2) -> CL | C34: CL01 | D34: 602 | E34: =VLOOKUP(Tabla1[[#This Row],[Grupo de compras]],'Grupo compras'!$A$1:$B$115,2,FALSE) -> CL Ops Mall | F34: R.Mesa | G34: =LEFT(Tabla1[[#This Row],[Solicitud de pedido]],2) -> 13 | H34: 1300008907 | I34: 10 | J34: 5000008653 | K34: SERVICIO CCTV 2026 | L34: 46072 | M34: MPINO | N34: ZSPC | P34: 99512120 | Q34: SECURITAS S.A | R34: 55887312 | S34: =Tabla1[[#This Row],[Valor total]]/'T.C.'!$B$3 -> 60358.031 | T34: CLP | U34: false
A35: 2400 | B35: =LEFT(Tabla1[[#This Row],[Organización compras]],2) -> CL | C35: CL01 | D35: 602 | E35: =VLOOKUP(Tabla1[[#This Row],[Grupo de compras]],'Grupo compras'!$A$1:$B$115,2,FALSE) -> CL Ops Mall | F35: RMESA | G35: =LEFT(Tabla1[[#This Row],[Solicitud de pedido]],2) -> 12 | H35: 1200145555 | I35: 10 | J35: 4900150043 | K35: Impermeabilización sector zocalo | L35: 46066 | M35: PCAMPOS | N35: ZSRV | P35: 76694376 | Q35: SERVICIOS INDUSTRIALES ELMEC LIMITA | R35: 52421617 | S35: =Tabla1[[#This Row],[Valor total]]/'T.C.'!$B$3 -> 56615.097 | T35: CLP | U35: false
A36: 1100 | B36: =LEFT(Tabla1[[#This Row],[Organización compras]],2) -> CL | C36: CL01 | D36: 602 | E36: =VLOOKUP(Tabla1[[#This Row],[Grupo de compras]],'Grupo compras'!$A$1:$B$115,2,FALSE) -> CL Ops Mall | F36: JFlores | G36: =LEFT(Tabla1[[#This Row],[Solicitud de pedido]],2) -> 13 | H36: 1300008929 | I36: 10 | J36: 5000008671 | K36: SP Kowski Delivery Sept- Dic 2026 | L36: 46085 | M36: JFLORES | N36: ZSPC | P36: 78232224 | Q36: SERVICIOS IKOW SPA | R36: 51000000 | S36: =Tabla1[[#This Row],[Valor total]]/'T.C.'!$B$3 -> 55079.758 | T36: CLP | U36: false
A37: MIN | B37: =LEFT(Tabla1[[#This Row],[Organización compras]],2) -> PE | C37: PE01 | D37: 802 | E37: =VLOOKUP(Tabla1[[#This Row],[Grupo de compras]],'Grupo compras'!$A$1:$B$115,2,FALSE) -> PE Ops Mall | F37: cpisfil | G37: =LEFT(Tabla1[[#This Row],[Solicitud de pedido]],2) -> 13 | H37: 1300008849 | I37: 10 | J37: 5000008588 | K37: serv op PTAR RM ene-dic 26 | L37: 46044 | M37: EXT_EDAVILA | N37: ZSPC | P37: P60384983 | Q37: FLOWEN S.A.C | R37: 186733.68 | S37: =Tabla1[[#This Row],[Valor total]]/'T.C.'!$B$2 -> 54125.704 | T37: PEN | U37: false
A38: MAM | B38: =LEFT(Tabla1[[#This Row],[Organización compras]],2) -> CL | C38: CL01 | D38: 634 | E38: =VLOOKUP(Tabla1[[#This Row],[Grupo de compras]],'Grupo compras'!$A$1:$B$115,2,FALSE) -> CL Proyectos 5 | F38: RSOUPER | G38: =LEFT(Tabla1[[#This Row],[Solicitud de pedido]],2) -> 12 | H38: 1200143928 | I38: 10 | J38: 4900148681 | K38: ITO Desmantelamiento Corona MAM | L38: 46035 | M38: EXT_AYEPEZ | N38: ZSRV | P38: 76088833 | Q38: ASESORIAS E INVERSIONES FAUNDEZ LAT | R38: 1246 | S38: =Tabla1[[#This Row],[Valor total]]/'T.C.'!$B$4 -> 51916.667 | T38: UF | U38: false
A39: 6000 | B39: =LEFT(Tabla1[[#This Row],[Organización compras]],2) -> PE | C39: PEMP | D39: 802 | E39: =VLOOKUP(Tabla1[[#This Row],[Grupo de compras]],'Grupo compras'!$A$1:$B$115,2,FALSE) -> PE Ops Mall | F39: KALVAN | G39: =LEFT(Tabla1[[#This Row],[Solicitud de pedido]],2) -> 12 | H39: 1200144795 | I39: 10 | J39: 4900149468 | K39: REVISIÓN_INDEPENDENCIA_ENERO_2026 | L39: 46051 | M39: EXT_KNOLASCO | N39: ZSRV | O39: SER_MANTO | P39: P49259204 | Q39: AF CONCEPT S.A.C. | R39: 178800 | S39: =Tabla1[[#This Row],[Valor total]]/'T.C.'!$B$2 -> 51826.087 | T39: PEN | U39: false
A40: 1100 | B40: =LEFT(Tabla1[[#This Row],[Organización compras]],2) -> CL | C40: CL01 | D40: 915 | E40: =VLOOKUP(Tabla1[[#This Row],[Grupo de compras]],'Grupo compras'!$A$1:$B$115,2,FALSE) -> Corp Des Digital | F40: N Gallardo | H40: 1300008973 | I40: 10 | J40: 5000008699 | K40: Equipo desarrollo P Locatario Q1 2026 | L40: 46099 | M40: NGALLARDO | N40: ZSPC | P40: 76516485 | Q40: APIUX TECNOLOGIA SPA | R40: 1230 | S40: =Tabla1[[#This Row],[Valor total]]/'T.C.'!$B$4 -> 51250 | T40: UF | U40: false
...

Sheet Grupo compras
A1: GCp | B1: Denominación
A2: 601 | B2: CL Center Manager
A3: 602 | B3: CL Ops Mall
A4: 603 | B4: CL Ops Out/Strip
A5: 604 | B5: CL Marketing Mall
A6: 605 | B6: CL Gcia Ing & Proy
A7: 606 | B7: CL Gcia Comercial
A8: 607 | B8: CL Gcia Desarrollo
A9: 608 | B9: CL Área Legal
A10: 609 | B10: CL GciaMarketing
A11: 610 | B11: CL Área Personas
A12: 611 | B12: CL Admin y C. Gest
A13: 612 | B13: CL Serv al Cliente
... A115: 941 | B115: Corp Negocios

Sheet T.D.
B1: Organización compras | C1: (Todas)
B2: Grupo de compras | C2: (Todas) | F2: Tipo | G2: (Varios elementos)
B3: Fecha de solicitud | C3: (Todas)
F4: Grupo de compras | G4: Cuenta de Pedido
B5: OCs creadas | C5: Valor USD | D5: % Representación | F5: Total general
B6: 4900149406 | C6: 271383.33 | D6: 0.0368888
B7: 4900148645 | C7: 153992.46 | D7: 0.020932005
B8: 4900148769 | C8: 142350 | D8: 0.019349459 | J8: Etiquetas de fila | K8: Cantd. Pedido | L8: Valor USD | M8: % Representación
B9: 4900149553 | C9: 134188.72 | D9: 0.018240107 | J9: DCL | K9: 1838 | L9: 21453146 | M9: 0.74947483
B10: 4900150865 | C10: 117439.13 | D10: 0.015963356 | J10: DPE | K10: 1256 | L10: 3113692.4 | M10: 0.10877818
B11: 4900150608 | C11: 110996.82 | D11: 0.01508766 | J11: PEMP | K11: 918 | L11: 2462281.7 | M11: 0.086020865
B12: 4900149369 | C12: 104166.67 | D12: 0.014159246 | J12: DCO | K12: 794 | L12: 1595118.1 | M12: 0.055726133
B13: 4900148958 | C13: 83083.333 | D13: 0.011293415 | J13: Total general | K13: 4806 | L13: 28624238 | M13: 1
B14: 4900149938 | C14: 69264.64 | D14: 0.0094150567
B15: 4900148892 | C15: 67000 | D15: 0.009107227
B16: 4900149771 | C16: 65217.39 | D16: 0.008864919
B17: 4900150043 | C17: 56615.097 | D17: 0.00769562
B18: 4900148681 | C18: 51916.667 | D18: 0.0070569682
B19: 4900149468 | C19: 51826.087 | D19: 0.0070446558
B20: 4900149430 | C20: 50000 | D20: 0.0067964381
B21: 4900149939 | C21: 46220.772 | D21: 0.0062827323
B22: 4900149641 | C22: 42719.167 | D22: 0.0058067634
B23: 4900149970 | C23: 42603.582 | D23: 0.0057910522
B24: 4900150564 | C24: 41487.5 | D24: 0.0056393445
B25: 4900150165 | C25: 41293.76 | D25: 0.0056130097
... B2677: Total general | C2677: 7356794.8 | D2677: 1

Sheet Prop. Mejora
B2: MEJORA DE CUMPLIMIENTO
M3: Propuesta de mejora:
A4: Mejora 1: Matriz de decisión obligatoria para el usuario | M4: Implementar un control preventivo en el proceso de compras para solicitudes mayores a USD 50,000, basado en una matriz estandarizada de selección de SolPed, alertas de validación y revisión previa por el área de Abastecimiento, a fin de asegurar que las compras sean gestionadas bajo la modalidad correcta según su monto, naturaleza contractual y nivel de criticidad.
A5: Proponer una matriz simple de selección de SolPed:
B6: SP 12: compras puntuales hasta cierto umbral y sin necesidad de contrato
B7: SP 13 / 14: compras de contrato o superiores a USD 50,000
B8: SP 15: procesos que por su naturaleza deben pasar por licitación o por gestión del otro equipo
A9: Esto debe quedar en una guía visual muy práctica, porque muchas veces la política existe, pero el usuario no la interpreta bien o elige lo más rápido.
A10: Beneficio
A11: Evita errores por desconocimiento y estandariza el criterio entre DCL, DCO, DPE, CORP
A13: Mejora 2: Validación automática o semiautomática por monto
A14: Propuesta | M14: Resultado esperado:
B15: Que se incorpore un flujo de aprobación obligatorio de Abastecimiento | M15: Reducir errores en la tipificación de SolPed, evitar desvíos de política, disminuir retrabajos y fortalecer la trazabilidad y el cumplimiento del proceso de compras en los distintos países y corporativo.
B16: La compra supere USD 20,000
A17: Modelo similar al de excepción de cotización

Sheet T.C.
A1: Tipo de cambio | C1: 46103
A2: PEN | B2: 3.45
A3: CLP | B3: 925.93
A4: UF | B4: 0.024
A5: COP | B5: 3678
A6: EURO | B6: 0.87

Sheet Pendientes
B3: * Establecer un tipo de cambio referencial de USD $: PEN,COP,CL,UF | H3: Al 31/03 (o al último reporte)
B4: * Verificar por tipo de compas, OC migradas, año actual, porque hay contratos migratorios y acumulativos
B5: Revisar
B6: Del total de OC al corte, cuántas superan USD 20.000
B7: 113 - OC 49* | C7: Revisar aquellas que no tienen contratos
C8: Proveedor y GC las OC 49*
B10: Elaborar una PPT con la data - Resultado del análisis
B12: Adicionar a la columna: Solicitantes
B13: Gráficos por países de cuánto USD tuvo CLP, CO, PE
